[2023-03-29 00:44:14,019] {taskinstance.py:1032} INFO - Dependencies all met for <TaskInstance: SP_500_DATA_PIPELINE_v2.ingest_to_gcs manual__2023-03-29T00:41:46.235533+00:00 [queued]>
[2023-03-29 00:44:14,059] {taskinstance.py:1032} INFO - Dependencies all met for <TaskInstance: SP_500_DATA_PIPELINE_v2.ingest_to_gcs manual__2023-03-29T00:41:46.235533+00:00 [queued]>
[2023-03-29 00:44:14,061] {taskinstance.py:1238} INFO - 
--------------------------------------------------------------------------------
[2023-03-29 00:44:14,063] {taskinstance.py:1239} INFO - Starting attempt 3 of 3
[2023-03-29 00:44:14,064] {taskinstance.py:1240} INFO - 
--------------------------------------------------------------------------------
[2023-03-29 00:44:14,107] {taskinstance.py:1259} INFO - Executing <Task(PythonOperator): ingest_to_gcs> on 2023-03-29 00:41:46.235533+00:00
[2023-03-29 00:44:14,117] {standard_task_runner.py:52} INFO - Started process 921 to run task
[2023-03-29 00:44:14,126] {standard_task_runner.py:76} INFO - Running: ['***', 'tasks', 'run', 'SP_500_DATA_PIPELINE_v2', 'ingest_to_gcs', 'manual__2023-03-29T00:41:46.235533+00:00', '--job-id', '37', '--raw', '--subdir', 'DAGS_FOLDER/first_dag.py', '--cfg-path', '/tmp/tmp5j8ydyie', '--error-file', '/tmp/tmpwdcin_bc']
[2023-03-29 00:44:14,130] {standard_task_runner.py:77} INFO - Job 37: Subtask ingest_to_gcs
[2023-03-29 00:44:14,266] {logging_mixin.py:109} INFO - Running <TaskInstance: SP_500_DATA_PIPELINE_v2.ingest_to_gcs manual__2023-03-29T00:41:46.235533+00:00 [running]> on host 67d8effe805a
[2023-03-29 00:44:14,417] {taskinstance.py:1426} INFO - Exporting the following env vars:
AIRFLOW_CTX_DAG_EMAIL=
AIRFLOW_CTX_DAG_OWNER=me
AIRFLOW_CTX_DAG_ID=SP_500_DATA_PIPELINE_v2
AIRFLOW_CTX_TASK_ID=ingest_to_gcs
AIRFLOW_CTX_EXECUTION_DATE=2023-03-29T00:41:46.235533+00:00
AIRFLOW_CTX_DAG_RUN_ID=manual__2023-03-29T00:41:46.235533+00:00
[2023-03-29 00:44:14,421] {taskinstance.py:1700} ERROR - Task failed with exception
Traceback (most recent call last):
  File "/home/airflow/.local/lib/python3.7/site-packages/airflow/models/taskinstance.py", line 1329, in _run_raw_task
    self._execute_task_with_callbacks(context)
  File "/home/airflow/.local/lib/python3.7/site-packages/airflow/models/taskinstance.py", line 1455, in _execute_task_with_callbacks
    result = self._execute_task(context, self.task)
  File "/home/airflow/.local/lib/python3.7/site-packages/airflow/models/taskinstance.py", line 1511, in _execute_task
    result = execute_callable(context=context)
  File "/home/airflow/.local/lib/python3.7/site-packages/airflow/operators/python.py", line 174, in execute
    return_value = self.execute_callable()
  File "/home/airflow/.local/lib/python3.7/site-packages/airflow/operators/python.py", line 185, in execute_callable
    return self.python_callable(*self.op_args, **self.op_kwargs)
  File "/opt/airflow/dags/etl_operation_functions.py", line 136, in upload_data_to_gcs_from_local
    credentials = get_gcp_authentication()
  File "/opt/airflow/dags/etl_operation_functions.py", line 51, in get_gcp_authentication
    credentials = service_account.Credentials.from_service_account_file(key_path)
  File "/home/airflow/.local/lib/python3.7/site-packages/google/oauth2/service_account.py", line 239, in from_service_account_file
    filename, require=["client_email", "token_uri"]
  File "/home/airflow/.local/lib/python3.7/site-packages/google/auth/_service_account_info.py", line 72, in from_filename
    with io.open(filename, "r", encoding="utf-8") as json_file:
FileNotFoundError: [Errno 2] No such file or directory: '/Users/falowogbolahan/.google/credentials/google_credentials.json'
[2023-03-29 00:44:14,464] {taskinstance.py:1277} INFO - Marking task as FAILED. dag_id=SP_500_DATA_PIPELINE_v2, task_id=ingest_to_gcs, execution_date=20230329T004146, start_date=20230329T004414, end_date=20230329T004414
[2023-03-29 00:44:14,510] {standard_task_runner.py:92} ERROR - Failed to execute job 37 for task ingest_to_gcs
Traceback (most recent call last):
  File "/home/airflow/.local/lib/python3.7/site-packages/airflow/task/task_runner/standard_task_runner.py", line 85, in _start_by_fork
    args.func(args, dag=self.dag)
  File "/home/airflow/.local/lib/python3.7/site-packages/airflow/cli/cli_parser.py", line 48, in command
    return func(*args, **kwargs)
  File "/home/airflow/.local/lib/python3.7/site-packages/airflow/utils/cli.py", line 92, in wrapper
    return f(*args, **kwargs)
  File "/home/airflow/.local/lib/python3.7/site-packages/airflow/cli/commands/task_command.py", line 298, in task_run
    _run_task_by_selected_method(args, dag, ti)
  File "/home/airflow/.local/lib/python3.7/site-packages/airflow/cli/commands/task_command.py", line 107, in _run_task_by_selected_method
    _run_raw_task(args, ti)
  File "/home/airflow/.local/lib/python3.7/site-packages/airflow/cli/commands/task_command.py", line 184, in _run_raw_task
    error_file=args.error_file,
  File "/home/airflow/.local/lib/python3.7/site-packages/airflow/utils/session.py", line 70, in wrapper
    return func(*args, session=session, **kwargs)
  File "/home/airflow/.local/lib/python3.7/site-packages/airflow/models/taskinstance.py", line 1329, in _run_raw_task
    self._execute_task_with_callbacks(context)
  File "/home/airflow/.local/lib/python3.7/site-packages/airflow/models/taskinstance.py", line 1455, in _execute_task_with_callbacks
    result = self._execute_task(context, self.task)
  File "/home/airflow/.local/lib/python3.7/site-packages/airflow/models/taskinstance.py", line 1511, in _execute_task
    result = execute_callable(context=context)
  File "/home/airflow/.local/lib/python3.7/site-packages/airflow/operators/python.py", line 174, in execute
    return_value = self.execute_callable()
  File "/home/airflow/.local/lib/python3.7/site-packages/airflow/operators/python.py", line 185, in execute_callable
    return self.python_callable(*self.op_args, **self.op_kwargs)
  File "/opt/airflow/dags/etl_operation_functions.py", line 136, in upload_data_to_gcs_from_local
    credentials = get_gcp_authentication()
  File "/opt/airflow/dags/etl_operation_functions.py", line 51, in get_gcp_authentication
    credentials = service_account.Credentials.from_service_account_file(key_path)
  File "/home/airflow/.local/lib/python3.7/site-packages/google/oauth2/service_account.py", line 239, in from_service_account_file
    filename, require=["client_email", "token_uri"]
  File "/home/airflow/.local/lib/python3.7/site-packages/google/auth/_service_account_info.py", line 72, in from_filename
    with io.open(filename, "r", encoding="utf-8") as json_file:
FileNotFoundError: [Errno 2] No such file or directory: '/Users/falowogbolahan/.google/credentials/google_credentials.json'
[2023-03-29 00:44:14,540] {local_task_job.py:154} INFO - Task exited with return code 1
[2023-03-29 00:44:14,650] {local_task_job.py:264} INFO - 0 downstream tasks scheduled from follow-on schedule check
