[2023-03-29 14:34:44,048] {taskinstance.py:1032} INFO - Dependencies all met for <TaskInstance: SP_500_DATA_PIPELINE_v1.transform_data_task manual__2023-03-29T14:34:09.749558+00:00 [queued]>
[2023-03-29 14:34:44,085] {taskinstance.py:1032} INFO - Dependencies all met for <TaskInstance: SP_500_DATA_PIPELINE_v1.transform_data_task manual__2023-03-29T14:34:09.749558+00:00 [queued]>
[2023-03-29 14:34:44,087] {taskinstance.py:1238} INFO - 
--------------------------------------------------------------------------------
[2023-03-29 14:34:44,088] {taskinstance.py:1239} INFO - Starting attempt 1 of 3
[2023-03-29 14:34:44,090] {taskinstance.py:1240} INFO - 
--------------------------------------------------------------------------------
[2023-03-29 14:34:44,127] {taskinstance.py:1259} INFO - Executing <Task(PythonOperator): transform_data_task> on 2023-03-29 14:34:09.749558+00:00
[2023-03-29 14:34:44,137] {standard_task_runner.py:52} INFO - Started process 510 to run task
[2023-03-29 14:34:44,146] {standard_task_runner.py:76} INFO - Running: ['***', 'tasks', 'run', 'SP_500_DATA_PIPELINE_v1', 'transform_data_task', 'manual__2023-03-29T14:34:09.749558+00:00', '--job-id', '132', '--raw', '--subdir', 'DAGS_FOLDER/first_dag.py', '--cfg-path', '/tmp/tmpwt4ky2g_', '--error-file', '/tmp/tmp7tbrxc1u']
[2023-03-29 14:34:44,149] {standard_task_runner.py:77} INFO - Job 132: Subtask transform_data_task
[2023-03-29 14:34:44,292] {logging_mixin.py:109} INFO - Running <TaskInstance: SP_500_DATA_PIPELINE_v1.transform_data_task manual__2023-03-29T14:34:09.749558+00:00 [running]> on host ebd786f8513c
[2023-03-29 14:34:44,469] {taskinstance.py:1426} INFO - Exporting the following env vars:
AIRFLOW_CTX_DAG_EMAIL=
AIRFLOW_CTX_DAG_OWNER=me
AIRFLOW_CTX_DAG_ID=SP_500_DATA_PIPELINE_v1
AIRFLOW_CTX_TASK_ID=transform_data_task
AIRFLOW_CTX_EXECUTION_DATE=2023-03-29T14:34:09.749558+00:00
AIRFLOW_CTX_DAG_RUN_ID=manual__2023-03-29T14:34:09.749558+00:00
[2023-03-29 14:40:32,701] {local_task_job.py:212} WARNING - State of this instance has been externally set to failed. Terminating instance.
[2023-03-29 14:40:32,764] {process_utils.py:124} INFO - Sending Signals.SIGTERM to group 510. PIDs of all processes in the group: [523, 510]
[2023-03-29 14:40:32,767] {process_utils.py:75} INFO - Sending the signal Signals.SIGTERM to group 510
[2023-03-29 14:40:32,774] {taskinstance.py:1408} ERROR - Received SIGTERM. Terminating subprocesses.
[2023-03-29 14:40:32,814] {clientserver.py:502} INFO - Error while receiving.
Traceback (most recent call last):
  File "/opt/spark/python/lib/py4j-0.10.9.3-src.zip/py4j/clientserver.py", line 475, in send_command
    answer = smart_decode(self.stream.readline()[:-1])
  File "/usr/local/lib/python3.7/socket.py", line 589, in readinto
    return self._sock.recv_into(b)
  File "/home/airflow/.local/lib/python3.7/site-packages/airflow/models/taskinstance.py", line 1410, in signal_handler
    raise AirflowException("Task received SIGTERM signal")
airflow.exceptions.AirflowException: Task received SIGTERM signal
[2023-03-29 14:40:32,850] {clientserver.py:507} INFO - Closing down clientserver connection
[2023-03-29 14:40:32,858] {java_gateway.py:1056} ERROR - Exception while sending command.
Traceback (most recent call last):
  File "/opt/spark/python/lib/py4j-0.10.9.3-src.zip/py4j/clientserver.py", line 475, in send_command
    answer = smart_decode(self.stream.readline()[:-1])
  File "/usr/local/lib/python3.7/socket.py", line 589, in readinto
    return self._sock.recv_into(b)
  File "/home/airflow/.local/lib/python3.7/site-packages/airflow/models/taskinstance.py", line 1410, in signal_handler
    raise AirflowException("Task received SIGTERM signal")
airflow.exceptions.AirflowException: Task received SIGTERM signal

During handling of the above exception, another exception occurred:

Traceback (most recent call last):
  File "/opt/spark/python/lib/py4j-0.10.9.3-src.zip/py4j/java_gateway.py", line 1038, in send_command
    response = connection.send_command(command)
  File "/opt/spark/python/lib/py4j-0.10.9.3-src.zip/py4j/clientserver.py", line 504, in send_command
    "Error while sending or receiving", e, proto.ERROR_ON_RECEIVE)
py4j.protocol.Py4JNetworkError: Error while sending or receiving
[2023-03-29 14:40:32,900] {taskinstance.py:1700} ERROR - Task failed with exception
Traceback (most recent call last):
  File "/home/airflow/.local/lib/python3.7/site-packages/airflow/models/taskinstance.py", line 1329, in _run_raw_task
    self._execute_task_with_callbacks(context)
  File "/home/airflow/.local/lib/python3.7/site-packages/airflow/models/taskinstance.py", line 1455, in _execute_task_with_callbacks
    result = self._execute_task(context, self.task)
  File "/home/airflow/.local/lib/python3.7/site-packages/airflow/models/taskinstance.py", line 1511, in _execute_task
    result = execute_callable(context=context)
  File "/home/airflow/.local/lib/python3.7/site-packages/airflow/operators/python.py", line 174, in execute
    return_value = self.execute_callable()
  File "/home/airflow/.local/lib/python3.7/site-packages/airflow/operators/python.py", line 185, in execute_callable
    return self.python_callable(*self.op_args, **self.op_kwargs)
  File "/opt/airflow/dags/stock_data_transform.py", line 49, in transform_stock_data
    df_spark = spark.read.csv(gcs_input_data_path, header=True, inferSchema=True)
  File "/opt/spark/python/pyspark/sql/readwriter.py", line 410, in csv
    return self._df(self._jreader.csv(self._spark._sc._jvm.PythonUtils.toSeq(path)))
  File "/opt/spark/python/lib/py4j-0.10.9.3-src.zip/py4j/java_gateway.py", line 1322, in __call__
    answer, self.gateway_client, self.target_id, self.name)
  File "/opt/spark/python/pyspark/sql/utils.py", line 111, in deco
    return f(*a, **kw)
  File "/opt/spark/python/lib/py4j-0.10.9.3-src.zip/py4j/protocol.py", line 336, in get_return_value
    format(target_id, ".", name))
py4j.protocol.Py4JError: An error occurred while calling o145.csv
[2023-03-29 14:40:33,134] {taskinstance.py:1277} INFO - Marking task as UP_FOR_RETRY. dag_id=SP_500_DATA_PIPELINE_v1, task_id=transform_data_task, execution_date=20230329T143409, start_date=20230329T143444, end_date=20230329T144033
[2023-03-29 14:40:33,463] {standard_task_runner.py:92} ERROR - Failed to execute job 132 for task transform_data_task
Traceback (most recent call last):
  File "/home/airflow/.local/lib/python3.7/site-packages/airflow/task/task_runner/standard_task_runner.py", line 85, in _start_by_fork
    args.func(args, dag=self.dag)
  File "/home/airflow/.local/lib/python3.7/site-packages/airflow/cli/cli_parser.py", line 48, in command
    return func(*args, **kwargs)
  File "/home/airflow/.local/lib/python3.7/site-packages/airflow/utils/cli.py", line 92, in wrapper
    return f(*args, **kwargs)
  File "/home/airflow/.local/lib/python3.7/site-packages/airflow/cli/commands/task_command.py", line 298, in task_run
    _run_task_by_selected_method(args, dag, ti)
  File "/home/airflow/.local/lib/python3.7/site-packages/airflow/cli/commands/task_command.py", line 107, in _run_task_by_selected_method
    _run_raw_task(args, ti)
  File "/home/airflow/.local/lib/python3.7/site-packages/airflow/cli/commands/task_command.py", line 184, in _run_raw_task
    error_file=args.error_file,
  File "/home/airflow/.local/lib/python3.7/site-packages/airflow/utils/session.py", line 70, in wrapper
    return func(*args, session=session, **kwargs)
  File "/home/airflow/.local/lib/python3.7/site-packages/airflow/models/taskinstance.py", line 1329, in _run_raw_task
    self._execute_task_with_callbacks(context)
  File "/home/airflow/.local/lib/python3.7/site-packages/airflow/models/taskinstance.py", line 1455, in _execute_task_with_callbacks
    result = self._execute_task(context, self.task)
  File "/home/airflow/.local/lib/python3.7/site-packages/airflow/models/taskinstance.py", line 1511, in _execute_task
    result = execute_callable(context=context)
  File "/home/airflow/.local/lib/python3.7/site-packages/airflow/operators/python.py", line 174, in execute
    return_value = self.execute_callable()
  File "/home/airflow/.local/lib/python3.7/site-packages/airflow/operators/python.py", line 185, in execute_callable
    return self.python_callable(*self.op_args, **self.op_kwargs)
  File "/opt/airflow/dags/stock_data_transform.py", line 49, in transform_stock_data
    df_spark = spark.read.csv(gcs_input_data_path, header=True, inferSchema=True)
  File "/opt/spark/python/pyspark/sql/readwriter.py", line 410, in csv
    return self._df(self._jreader.csv(self._spark._sc._jvm.PythonUtils.toSeq(path)))
  File "/opt/spark/python/lib/py4j-0.10.9.3-src.zip/py4j/java_gateway.py", line 1322, in __call__
    answer, self.gateway_client, self.target_id, self.name)
  File "/opt/spark/python/pyspark/sql/utils.py", line 111, in deco
    return f(*a, **kw)
  File "/opt/spark/python/lib/py4j-0.10.9.3-src.zip/py4j/protocol.py", line 336, in get_return_value
    format(target_id, ".", name))
py4j.protocol.Py4JError: An error occurred while calling o145.csv
[2023-03-29 14:40:33,839] {process_utils.py:70} INFO - Process psutil.Process(pid=510, status='terminated', exitcode=1, started='14:34:43') (510) terminated with exit code 1
[2023-03-29 14:41:32,784] {process_utils.py:138} WARNING - process psutil.Process(pid=523, name='java', status='sleeping', started='14:34:43') did not respond to SIGTERM. Trying SIGKILL
[2023-03-29 14:41:32,804] {process_utils.py:75} INFO - Sending the signal Signals.SIGKILL to group 510
[2023-03-29 14:41:33,524] {process_utils.py:70} INFO - Process psutil.Process(pid=523, name='java', status='terminated', started='14:34:43') (523) terminated with exit code None
