[2023-04-12 18:55:02,783] {taskinstance.py:1026} INFO - Dependencies not met for <TaskInstance: SP_500_DATA_PIPELINE_v1.transform_data_task manual__2023-04-12T18:19:27.143756+00:00 [up_for_retry]>, dependency 'Not In Retry Period' FAILED: Task is not ready for retry yet but will be retried automatically. Current date is 2023-04-12T18:55:02.766116+00:00 and task will be retried at 2023-04-12T18:55:39.587260+00:00.
[2023-04-12 18:55:03,016] {local_task_job.py:99} INFO - Task is not able to be run
[2023-04-12 18:56:13,283] {taskinstance.py:1032} INFO - Dependencies all met for <TaskInstance: SP_500_DATA_PIPELINE_v1.transform_data_task manual__2023-04-12T18:19:27.143756+00:00 [queued]>
[2023-04-12 18:56:13,494] {taskinstance.py:1032} INFO - Dependencies all met for <TaskInstance: SP_500_DATA_PIPELINE_v1.transform_data_task manual__2023-04-12T18:19:27.143756+00:00 [queued]>
[2023-04-12 18:56:13,497] {taskinstance.py:1238} INFO - 
--------------------------------------------------------------------------------
[2023-04-12 18:56:13,501] {taskinstance.py:1239} INFO - Starting attempt 3 of 3
[2023-04-12 18:56:13,503] {taskinstance.py:1240} INFO - 
--------------------------------------------------------------------------------
[2023-04-12 18:56:13,937] {taskinstance.py:1259} INFO - Executing <Task(PythonOperator): transform_data_task> on 2023-04-12 18:19:27.143756+00:00
[2023-04-12 18:56:14,002] {standard_task_runner.py:52} INFO - Started process 1860 to run task
[2023-04-12 18:56:14,091] {standard_task_runner.py:76} INFO - Running: ['***', 'tasks', 'run', 'SP_500_DATA_PIPELINE_v1', 'transform_data_task', 'manual__2023-04-12T18:19:27.143756+00:00', '--job-id', '214', '--raw', '--subdir', 'DAGS_FOLDER/sp_500_data_processing_dag.py', '--cfg-path', '/tmp/tmpdz5fjg1r', '--error-file', '/tmp/tmp8e3h69f1']
[2023-04-12 18:56:14,107] {standard_task_runner.py:77} INFO - Job 214: Subtask transform_data_task
[2023-04-12 18:56:14,994] {logging_mixin.py:109} INFO - Running <TaskInstance: SP_500_DATA_PIPELINE_v1.transform_data_task manual__2023-04-12T18:19:27.143756+00:00 [running]> on host 7b33c6d8ff37
[2023-04-12 18:56:16,284] {taskinstance.py:1426} INFO - Exporting the following env vars:
AIRFLOW_CTX_DAG_EMAIL=
AIRFLOW_CTX_DAG_OWNER=me
AIRFLOW_CTX_DAG_ID=SP_500_DATA_PIPELINE_v1
AIRFLOW_CTX_TASK_ID=transform_data_task
AIRFLOW_CTX_EXECUTION_DATE=2023-04-12T18:19:27.143756+00:00
AIRFLOW_CTX_DAG_RUN_ID=manual__2023-04-12T18:19:27.143756+00:00
[2023-04-12 22:20:29,994] {local_task_job.py:212} WARNING - State of this instance has been externally set to failed. Terminating instance.
[2023-04-12 22:20:30,026] {process_utils.py:124} INFO - Sending Signals.SIGTERM to group 1860. PIDs of all processes in the group: [1862, 1860]
[2023-04-12 22:20:30,030] {process_utils.py:75} INFO - Sending the signal Signals.SIGTERM to group 1860
[2023-04-12 22:20:30,036] {taskinstance.py:1408} ERROR - Received SIGTERM. Terminating subprocesses.
[2023-04-12 22:20:30,043] {clientserver.py:502} INFO - Error while receiving.
Traceback (most recent call last):
  File "/opt/spark/python/lib/py4j-0.10.9.3-src.zip/py4j/clientserver.py", line 475, in send_command
    answer = smart_decode(self.stream.readline()[:-1])
  File "/usr/local/lib/python3.7/socket.py", line 589, in readinto
    return self._sock.recv_into(b)
  File "/home/airflow/.local/lib/python3.7/site-packages/airflow/models/taskinstance.py", line 1410, in signal_handler
    raise AirflowException("Task received SIGTERM signal")
airflow.exceptions.AirflowException: Task received SIGTERM signal
[2023-04-12 22:20:30,089] {clientserver.py:507} INFO - Closing down clientserver connection
[2023-04-12 22:20:30,093] {java_gateway.py:1056} ERROR - Exception while sending command.
Traceback (most recent call last):
  File "/opt/spark/python/lib/py4j-0.10.9.3-src.zip/py4j/clientserver.py", line 475, in send_command
    answer = smart_decode(self.stream.readline()[:-1])
  File "/usr/local/lib/python3.7/socket.py", line 589, in readinto
    return self._sock.recv_into(b)
  File "/home/airflow/.local/lib/python3.7/site-packages/airflow/models/taskinstance.py", line 1410, in signal_handler
    raise AirflowException("Task received SIGTERM signal")
airflow.exceptions.AirflowException: Task received SIGTERM signal

During handling of the above exception, another exception occurred:

Traceback (most recent call last):
  File "/opt/spark/python/lib/py4j-0.10.9.3-src.zip/py4j/java_gateway.py", line 1038, in send_command
    response = connection.send_command(command)
  File "/opt/spark/python/lib/py4j-0.10.9.3-src.zip/py4j/clientserver.py", line 504, in send_command
    "Error while sending or receiving", e, proto.ERROR_ON_RECEIVE)
py4j.protocol.Py4JNetworkError: Error while sending or receiving
[2023-04-12 22:20:30,113] {stock_data_transform.py:134} ERROR - An error occurred during transformation: An error occurred while calling o283.csv
[2023-04-12 22:21:30,049] {process_utils.py:138} WARNING - process psutil.Process(pid=1860, name='airflow task ru', status='sleeping', started='18:56:13') did not respond to SIGTERM. Trying SIGKILL
[2023-04-12 22:21:30,108] {process_utils.py:138} WARNING - process psutil.Process(pid=1862, name='java', status='sleeping', started='18:56:15') did not respond to SIGTERM. Trying SIGKILL
[2023-04-12 22:21:30,119] {process_utils.py:75} INFO - Sending the signal Signals.SIGKILL to group 1860
[2023-04-12 22:21:30,318] {process_utils.py:70} INFO - Process psutil.Process(pid=1860, name='airflow task ru', status='terminated', exitcode=<Negsignal.SIGKILL: -9>, started='18:56:13') (1860) terminated with exit code Negsignal.SIGKILL
[2023-04-12 22:21:32,248] {process_utils.py:70} INFO - Process psutil.Process(pid=1862, name='java', status='terminated', started='18:56:15') (1862) terminated with exit code None
[2023-04-12 22:21:32,272] {standard_task_runner.py:135} ERROR - Job 214 was killed before it finished (likely due to running out of memory)
