[2023-03-28 23:59:26,776] {taskinstance.py:1032} INFO - Dependencies all met for <TaskInstance: SP_500_DATA_PIPELINE_v2.extract_data_task manual__2023-03-28T23:58:05.065917+00:00 [queued]>
[2023-03-28 23:59:26,823] {taskinstance.py:1032} INFO - Dependencies all met for <TaskInstance: SP_500_DATA_PIPELINE_v2.extract_data_task manual__2023-03-28T23:58:05.065917+00:00 [queued]>
[2023-03-28 23:59:26,825] {taskinstance.py:1238} INFO - 
--------------------------------------------------------------------------------
[2023-03-28 23:59:26,826] {taskinstance.py:1239} INFO - Starting attempt 2 of 3
[2023-03-28 23:59:26,828] {taskinstance.py:1240} INFO - 
--------------------------------------------------------------------------------
[2023-03-28 23:59:26,871] {taskinstance.py:1259} INFO - Executing <Task(PythonOperator): extract_data_task> on 2023-03-28 23:58:05.065917+00:00
[2023-03-28 23:59:26,881] {standard_task_runner.py:52} INFO - Started process 950 to run task
[2023-03-28 23:59:26,890] {standard_task_runner.py:76} INFO - Running: ['***', 'tasks', 'run', 'SP_500_DATA_PIPELINE_v2', 'extract_data_task', 'manual__2023-03-28T23:58:05.065917+00:00', '--job-id', '22', '--raw', '--subdir', 'DAGS_FOLDER/first_dag.py', '--cfg-path', '/tmp/tmpllbxcj84', '--error-file', '/tmp/tmpdaubuh1x']
[2023-03-28 23:59:26,893] {standard_task_runner.py:77} INFO - Job 22: Subtask extract_data_task
[2023-03-28 23:59:27,020] {logging_mixin.py:109} INFO - Running <TaskInstance: SP_500_DATA_PIPELINE_v2.extract_data_task manual__2023-03-28T23:58:05.065917+00:00 [running]> on host 092c34bd7a0c
[2023-03-28 23:59:27,155] {taskinstance.py:1426} INFO - Exporting the following env vars:
AIRFLOW_CTX_DAG_EMAIL=
AIRFLOW_CTX_DAG_OWNER=me
AIRFLOW_CTX_DAG_ID=SP_500_DATA_PIPELINE_v2
AIRFLOW_CTX_TASK_ID=extract_data_task
AIRFLOW_CTX_EXECUTION_DATE=2023-03-28T23:58:05.065917+00:00
AIRFLOW_CTX_DAG_RUN_ID=manual__2023-03-28T23:58:05.065917+00:00
[2023-03-28 23:59:29,593] {logging_mixin.py:109} INFO - Error while extracting data for AAPL: The tiingo API key must be provided either through the api_key variable or through the environmental variable TIINGO_API_KEY.
[2023-03-28 23:59:29,596] {logging_mixin.py:109} INFO - Failed to retrieve data for the following tickers: ['AAPL']
[2023-03-28 23:59:29,598] {taskinstance.py:1700} ERROR - Task failed with exception
Traceback (most recent call last):
  File "/home/airflow/.local/lib/python3.7/site-packages/airflow/models/taskinstance.py", line 1329, in _run_raw_task
    self._execute_task_with_callbacks(context)
  File "/home/airflow/.local/lib/python3.7/site-packages/airflow/models/taskinstance.py", line 1455, in _execute_task_with_callbacks
    result = self._execute_task(context, self.task)
  File "/home/airflow/.local/lib/python3.7/site-packages/airflow/models/taskinstance.py", line 1511, in _execute_task
    result = execute_callable(context=context)
  File "/home/airflow/.local/lib/python3.7/site-packages/airflow/operators/python.py", line 174, in execute
    return_value = self.execute_callable()
  File "/home/airflow/.local/lib/python3.7/site-packages/airflow/operators/python.py", line 185, in execute_callable
    return self.python_callable(*self.op_args, **self.op_kwargs)
  File "/opt/airflow/dags/etl_operation_functions.py", line 105, in extract_sp500_data_to_csv
    df = pd.concat(successful_tickers)
  File "/home/airflow/.local/lib/python3.7/site-packages/pandas/util/_decorators.py", line 311, in wrapper
    return func(*args, **kwargs)
  File "/home/airflow/.local/lib/python3.7/site-packages/pandas/core/reshape/concat.py", line 304, in concat
    sort=sort,
  File "/home/airflow/.local/lib/python3.7/site-packages/pandas/core/reshape/concat.py", line 351, in __init__
    raise ValueError("No objects to concatenate")
ValueError: No objects to concatenate
[2023-03-28 23:59:29,647] {taskinstance.py:1277} INFO - Marking task as UP_FOR_RETRY. dag_id=SP_500_DATA_PIPELINE_v2, task_id=extract_data_task, execution_date=20230328T235805, start_date=20230328T235926, end_date=20230328T235929
[2023-03-28 23:59:29,709] {standard_task_runner.py:92} ERROR - Failed to execute job 22 for task extract_data_task
Traceback (most recent call last):
  File "/home/airflow/.local/lib/python3.7/site-packages/airflow/task/task_runner/standard_task_runner.py", line 85, in _start_by_fork
    args.func(args, dag=self.dag)
  File "/home/airflow/.local/lib/python3.7/site-packages/airflow/cli/cli_parser.py", line 48, in command
    return func(*args, **kwargs)
  File "/home/airflow/.local/lib/python3.7/site-packages/airflow/utils/cli.py", line 92, in wrapper
    return f(*args, **kwargs)
  File "/home/airflow/.local/lib/python3.7/site-packages/airflow/cli/commands/task_command.py", line 298, in task_run
    _run_task_by_selected_method(args, dag, ti)
  File "/home/airflow/.local/lib/python3.7/site-packages/airflow/cli/commands/task_command.py", line 107, in _run_task_by_selected_method
    _run_raw_task(args, ti)
  File "/home/airflow/.local/lib/python3.7/site-packages/airflow/cli/commands/task_command.py", line 184, in _run_raw_task
    error_file=args.error_file,
  File "/home/airflow/.local/lib/python3.7/site-packages/airflow/utils/session.py", line 70, in wrapper
    return func(*args, session=session, **kwargs)
  File "/home/airflow/.local/lib/python3.7/site-packages/airflow/models/taskinstance.py", line 1329, in _run_raw_task
    self._execute_task_with_callbacks(context)
  File "/home/airflow/.local/lib/python3.7/site-packages/airflow/models/taskinstance.py", line 1455, in _execute_task_with_callbacks
    result = self._execute_task(context, self.task)
  File "/home/airflow/.local/lib/python3.7/site-packages/airflow/models/taskinstance.py", line 1511, in _execute_task
    result = execute_callable(context=context)
  File "/home/airflow/.local/lib/python3.7/site-packages/airflow/operators/python.py", line 174, in execute
    return_value = self.execute_callable()
  File "/home/airflow/.local/lib/python3.7/site-packages/airflow/operators/python.py", line 185, in execute_callable
    return self.python_callable(*self.op_args, **self.op_kwargs)
  File "/opt/airflow/dags/etl_operation_functions.py", line 105, in extract_sp500_data_to_csv
    df = pd.concat(successful_tickers)
  File "/home/airflow/.local/lib/python3.7/site-packages/pandas/util/_decorators.py", line 311, in wrapper
    return func(*args, **kwargs)
  File "/home/airflow/.local/lib/python3.7/site-packages/pandas/core/reshape/concat.py", line 304, in concat
    sort=sort,
  File "/home/airflow/.local/lib/python3.7/site-packages/pandas/core/reshape/concat.py", line 351, in __init__
    raise ValueError("No objects to concatenate")
ValueError: No objects to concatenate
[2023-03-28 23:59:29,762] {local_task_job.py:154} INFO - Task exited with return code 1
[2023-03-28 23:59:29,943] {local_task_job.py:264} INFO - 0 downstream tasks scheduled from follow-on schedule check
