[2023-06-03 00:16:37,139] {taskinstance.py:1032} INFO - Dependencies all met for <TaskInstance: SP_500_DATA_PIPELINE_v1.ingest_to_gcs manual__2023-06-03T00:07:12+00:00 [queued]>
[2023-06-03 00:16:37,194] {taskinstance.py:1032} INFO - Dependencies all met for <TaskInstance: SP_500_DATA_PIPELINE_v1.ingest_to_gcs manual__2023-06-03T00:07:12+00:00 [queued]>
[2023-06-03 00:16:37,197] {taskinstance.py:1238} INFO - 
--------------------------------------------------------------------------------
[2023-06-03 00:16:37,199] {taskinstance.py:1239} INFO - Starting attempt 1 of 3
[2023-06-03 00:16:37,200] {taskinstance.py:1240} INFO - 
--------------------------------------------------------------------------------
[2023-06-03 00:16:37,248] {taskinstance.py:1259} INFO - Executing <Task(PythonOperator): ingest_to_gcs> on 2023-06-03 00:07:12+00:00
[2023-06-03 00:16:37,263] {standard_task_runner.py:52} INFO - Started process 1188 to run task
[2023-06-03 00:16:37,272] {standard_task_runner.py:76} INFO - Running: ['***', 'tasks', 'run', 'SP_500_DATA_PIPELINE_v1', 'ingest_to_gcs', 'manual__2023-06-03T00:07:12+00:00', '--job-id', '232', '--raw', '--subdir', 'DAGS_FOLDER/sp_500_data_processing_dag.py', '--cfg-path', '/tmp/tmp4elvh1cn', '--error-file', '/tmp/tmpbosx_pp8']
[2023-06-03 00:16:37,276] {standard_task_runner.py:77} INFO - Job 232: Subtask ingest_to_gcs
[2023-06-03 00:16:37,421] {logging_mixin.py:109} INFO - Running <TaskInstance: SP_500_DATA_PIPELINE_v1.ingest_to_gcs manual__2023-06-03T00:07:12+00:00 [running]> on host 500eb760e513
[2023-06-03 00:16:37,587] {taskinstance.py:1426} INFO - Exporting the following env vars:
AIRFLOW_CTX_DAG_EMAIL=
AIRFLOW_CTX_DAG_OWNER=me
AIRFLOW_CTX_DAG_ID=SP_500_DATA_PIPELINE_v1
AIRFLOW_CTX_TASK_ID=ingest_to_gcs
AIRFLOW_CTX_EXECUTION_DATE=2023-06-03T00:07:12+00:00
AIRFLOW_CTX_DAG_RUN_ID=manual__2023-06-03T00:07:12+00:00
[2023-06-03 00:16:38,811] {taskinstance.py:1700} ERROR - Task failed with exception
Traceback (most recent call last):
  File "/home/airflow/.local/lib/python3.7/site-packages/google/cloud/storage/blob.py", line 2594, in upload_from_file
    retry=retry,
  File "/home/airflow/.local/lib/python3.7/site-packages/google/cloud/storage/blob.py", line 2412, in _do_upload
    retry=retry,
  File "/home/airflow/.local/lib/python3.7/site-packages/google/cloud/storage/blob.py", line 2237, in _do_resumable_upload
    retry=retry,
  File "/home/airflow/.local/lib/python3.7/site-packages/google/cloud/storage/blob.py", line 2112, in _initiate_resumable_upload
    timeout=timeout,
  File "/home/airflow/.local/lib/python3.7/site-packages/google/resumable_media/requests/upload.py", line 421, in initiate
    retriable_request, self._get_status_code, self._retry_strategy
  File "/home/airflow/.local/lib/python3.7/site-packages/google/resumable_media/requests/_request_helpers.py", line 147, in wait_and_retry
    response = func()
  File "/home/airflow/.local/lib/python3.7/site-packages/google/resumable_media/requests/upload.py", line 416, in retriable_request
    self._process_initiate_response(result)
  File "/home/airflow/.local/lib/python3.7/site-packages/google/resumable_media/_upload.py", line 503, in _process_initiate_response
    callback=self._make_invalid,
  File "/home/airflow/.local/lib/python3.7/site-packages/google/resumable_media/_helpers.py", line 104, in require_status_code
    *status_codes
google.resumable_media.common.InvalidResponse: ('Request failed with status code', 403, 'Expected one of', <HTTPStatus.OK: 200>, <HTTPStatus.CREATED: 201>)

During handling of the above exception, another exception occurred:

Traceback (most recent call last):
  File "/home/airflow/.local/lib/python3.7/site-packages/airflow/models/taskinstance.py", line 1329, in _run_raw_task
    self._execute_task_with_callbacks(context)
  File "/home/airflow/.local/lib/python3.7/site-packages/airflow/models/taskinstance.py", line 1455, in _execute_task_with_callbacks
    result = self._execute_task(context, self.task)
  File "/home/airflow/.local/lib/python3.7/site-packages/airflow/models/taskinstance.py", line 1511, in _execute_task
    result = execute_callable(context=context)
  File "/home/airflow/.local/lib/python3.7/site-packages/airflow/operators/python.py", line 174, in execute
    return_value = self.execute_callable()
  File "/home/airflow/.local/lib/python3.7/site-packages/airflow/operators/python.py", line 185, in execute_callable
    return self.python_callable(*self.op_args, **self.op_kwargs)
  File "/opt/airflow/dags/helper_functions.py", line 128, in upload_data_to_gcs_from_local
    blob.upload_from_filename(source_file_path_local)
  File "/home/airflow/.local/lib/python3.7/site-packages/google/cloud/storage/blob.py", line 2735, in upload_from_filename
    retry=retry,
  File "/home/airflow/.local/lib/python3.7/site-packages/google/cloud/storage/blob.py", line 2598, in upload_from_file
    _raise_from_invalid_response(exc)
  File "/home/airflow/.local/lib/python3.7/site-packages/google/cloud/storage/blob.py", line 4466, in _raise_from_invalid_response
    raise exceptions.from_http_status(response.status_code, message, response=response)
google.api_core.exceptions.Forbidden: 403 POST https://storage.googleapis.com/upload/storage/v1/b/dtc_data_lake_dataengineering-378316/o?uploadType=resumable: {
  "error": {
    "code": 403,
    "message": "The billing account for the owning project is disabled in state absent",
    "errors": [
      {
        "message": "The billing account for the owning project is disabled in state absent",
        "domain": "global",
        "reason": "accountDisabled",
        "locationType": "header",
        "location": "Authorization"
      }
    ]
  }
}
: ('Request failed with status code', 403, 'Expected one of', <HTTPStatus.OK: 200>, <HTTPStatus.CREATED: 201>)
[2023-06-03 00:16:38,883] {taskinstance.py:1277} INFO - Marking task as UP_FOR_RETRY. dag_id=SP_500_DATA_PIPELINE_v1, task_id=ingest_to_gcs, execution_date=20230603T000712, start_date=20230603T001637, end_date=20230603T001638
[2023-06-03 00:16:38,958] {standard_task_runner.py:92} ERROR - Failed to execute job 232 for task ingest_to_gcs
Traceback (most recent call last):
  File "/home/airflow/.local/lib/python3.7/site-packages/google/cloud/storage/blob.py", line 2594, in upload_from_file
    retry=retry,
  File "/home/airflow/.local/lib/python3.7/site-packages/google/cloud/storage/blob.py", line 2412, in _do_upload
    retry=retry,
  File "/home/airflow/.local/lib/python3.7/site-packages/google/cloud/storage/blob.py", line 2237, in _do_resumable_upload
    retry=retry,
  File "/home/airflow/.local/lib/python3.7/site-packages/google/cloud/storage/blob.py", line 2112, in _initiate_resumable_upload
    timeout=timeout,
  File "/home/airflow/.local/lib/python3.7/site-packages/google/resumable_media/requests/upload.py", line 421, in initiate
    retriable_request, self._get_status_code, self._retry_strategy
  File "/home/airflow/.local/lib/python3.7/site-packages/google/resumable_media/requests/_request_helpers.py", line 147, in wait_and_retry
    response = func()
  File "/home/airflow/.local/lib/python3.7/site-packages/google/resumable_media/requests/upload.py", line 416, in retriable_request
    self._process_initiate_response(result)
  File "/home/airflow/.local/lib/python3.7/site-packages/google/resumable_media/_upload.py", line 503, in _process_initiate_response
    callback=self._make_invalid,
  File "/home/airflow/.local/lib/python3.7/site-packages/google/resumable_media/_helpers.py", line 104, in require_status_code
    *status_codes
google.resumable_media.common.InvalidResponse: ('Request failed with status code', 403, 'Expected one of', <HTTPStatus.OK: 200>, <HTTPStatus.CREATED: 201>)

During handling of the above exception, another exception occurred:

Traceback (most recent call last):
  File "/home/airflow/.local/lib/python3.7/site-packages/airflow/task/task_runner/standard_task_runner.py", line 85, in _start_by_fork
    args.func(args, dag=self.dag)
  File "/home/airflow/.local/lib/python3.7/site-packages/airflow/cli/cli_parser.py", line 48, in command
    return func(*args, **kwargs)
  File "/home/airflow/.local/lib/python3.7/site-packages/airflow/utils/cli.py", line 92, in wrapper
    return f(*args, **kwargs)
  File "/home/airflow/.local/lib/python3.7/site-packages/airflow/cli/commands/task_command.py", line 298, in task_run
    _run_task_by_selected_method(args, dag, ti)
  File "/home/airflow/.local/lib/python3.7/site-packages/airflow/cli/commands/task_command.py", line 107, in _run_task_by_selected_method
    _run_raw_task(args, ti)
  File "/home/airflow/.local/lib/python3.7/site-packages/airflow/cli/commands/task_command.py", line 184, in _run_raw_task
    error_file=args.error_file,
  File "/home/airflow/.local/lib/python3.7/site-packages/airflow/utils/session.py", line 70, in wrapper
    return func(*args, session=session, **kwargs)
  File "/home/airflow/.local/lib/python3.7/site-packages/airflow/models/taskinstance.py", line 1329, in _run_raw_task
    self._execute_task_with_callbacks(context)
  File "/home/airflow/.local/lib/python3.7/site-packages/airflow/models/taskinstance.py", line 1455, in _execute_task_with_callbacks
    result = self._execute_task(context, self.task)
  File "/home/airflow/.local/lib/python3.7/site-packages/airflow/models/taskinstance.py", line 1511, in _execute_task
    result = execute_callable(context=context)
  File "/home/airflow/.local/lib/python3.7/site-packages/airflow/operators/python.py", line 174, in execute
    return_value = self.execute_callable()
  File "/home/airflow/.local/lib/python3.7/site-packages/airflow/operators/python.py", line 185, in execute_callable
    return self.python_callable(*self.op_args, **self.op_kwargs)
  File "/opt/airflow/dags/helper_functions.py", line 128, in upload_data_to_gcs_from_local
    blob.upload_from_filename(source_file_path_local)
  File "/home/airflow/.local/lib/python3.7/site-packages/google/cloud/storage/blob.py", line 2735, in upload_from_filename
    retry=retry,
  File "/home/airflow/.local/lib/python3.7/site-packages/google/cloud/storage/blob.py", line 2598, in upload_from_file
    _raise_from_invalid_response(exc)
  File "/home/airflow/.local/lib/python3.7/site-packages/google/cloud/storage/blob.py", line 4466, in _raise_from_invalid_response
    raise exceptions.from_http_status(response.status_code, message, response=response)
google.api_core.exceptions.Forbidden: 403 POST https://storage.googleapis.com/upload/storage/v1/b/dtc_data_lake_dataengineering-378316/o?uploadType=resumable: {
  "error": {
    "code": 403,
    "message": "The billing account for the owning project is disabled in state absent",
    "errors": [
      {
        "message": "The billing account for the owning project is disabled in state absent",
        "domain": "global",
        "reason": "accountDisabled",
        "locationType": "header",
        "location": "Authorization"
      }
    ]
  }
}
: ('Request failed with status code', 403, 'Expected one of', <HTTPStatus.OK: 200>, <HTTPStatus.CREATED: 201>)
[2023-06-03 00:16:39,036] {local_task_job.py:154} INFO - Task exited with return code 1
[2023-06-03 00:16:39,204] {local_task_job.py:264} INFO - 0 downstream tasks scheduled from follow-on schedule check
