[2023-03-29 16:39:06,261] {taskinstance.py:1032} INFO - Dependencies all met for <TaskInstance: SP_500_DATA_PIPELINE_v1.transform_data_task manual__2023-03-29T16:38:42.726218+00:00 [queued]>
[2023-03-29 16:39:06,298] {taskinstance.py:1032} INFO - Dependencies all met for <TaskInstance: SP_500_DATA_PIPELINE_v1.transform_data_task manual__2023-03-29T16:38:42.726218+00:00 [queued]>
[2023-03-29 16:39:06,299] {taskinstance.py:1238} INFO - 
--------------------------------------------------------------------------------
[2023-03-29 16:39:06,301] {taskinstance.py:1239} INFO - Starting attempt 1 of 3
[2023-03-29 16:39:06,302] {taskinstance.py:1240} INFO - 
--------------------------------------------------------------------------------
[2023-03-29 16:39:06,343] {taskinstance.py:1259} INFO - Executing <Task(PythonOperator): transform_data_task> on 2023-03-29 16:38:42.726218+00:00
[2023-03-29 16:39:06,353] {standard_task_runner.py:52} INFO - Started process 7456 to run task
[2023-03-29 16:39:06,362] {standard_task_runner.py:76} INFO - Running: ['***', 'tasks', 'run', 'SP_500_DATA_PIPELINE_v1', 'transform_data_task', 'manual__2023-03-29T16:38:42.726218+00:00', '--job-id', '147', '--raw', '--subdir', 'DAGS_FOLDER/first_dag.py', '--cfg-path', '/tmp/tmpu0fnz65a', '--error-file', '/tmp/tmpy1wrrr98']
[2023-03-29 16:39:06,365] {standard_task_runner.py:77} INFO - Job 147: Subtask transform_data_task
[2023-03-29 16:39:06,516] {logging_mixin.py:109} INFO - Running <TaskInstance: SP_500_DATA_PIPELINE_v1.transform_data_task manual__2023-03-29T16:38:42.726218+00:00 [running]> on host ebd786f8513c
[2023-03-29 16:39:06,673] {taskinstance.py:1426} INFO - Exporting the following env vars:
AIRFLOW_CTX_DAG_EMAIL=
AIRFLOW_CTX_DAG_OWNER=me
AIRFLOW_CTX_DAG_ID=SP_500_DATA_PIPELINE_v1
AIRFLOW_CTX_TASK_ID=transform_data_task
AIRFLOW_CTX_EXECUTION_DATE=2023-03-29T16:38:42.726218+00:00
AIRFLOW_CTX_DAG_RUN_ID=manual__2023-03-29T16:38:42.726218+00:00
[2023-03-29 16:39:42,662] {local_task_job.py:212} WARNING - State of this instance has been externally set to failed. Terminating instance.
[2023-03-29 16:39:42,701] {process_utils.py:124} INFO - Sending Signals.SIGTERM to group 7456. PIDs of all processes in the group: [7458, 7456]
[2023-03-29 16:39:42,704] {process_utils.py:75} INFO - Sending the signal Signals.SIGTERM to group 7456
[2023-03-29 16:39:42,724] {taskinstance.py:1408} ERROR - Received SIGTERM. Terminating subprocesses.
[2023-03-29 16:39:42,736] {clientserver.py:502} INFO - Error while receiving.
Traceback (most recent call last):
  File "/opt/spark/python/lib/py4j-0.10.9.3-src.zip/py4j/clientserver.py", line 475, in send_command
    answer = smart_decode(self.stream.readline()[:-1])
  File "/usr/local/lib/python3.7/socket.py", line 589, in readinto
    return self._sock.recv_into(b)
  File "/home/airflow/.local/lib/python3.7/site-packages/airflow/models/taskinstance.py", line 1410, in signal_handler
    raise AirflowException("Task received SIGTERM signal")
airflow.exceptions.AirflowException: Task received SIGTERM signal
[2023-03-29 16:39:42,781] {clientserver.py:507} INFO - Closing down clientserver connection
[2023-03-29 16:39:42,785] {java_gateway.py:1056} ERROR - Exception while sending command.
Traceback (most recent call last):
  File "/opt/spark/python/lib/py4j-0.10.9.3-src.zip/py4j/clientserver.py", line 475, in send_command
    answer = smart_decode(self.stream.readline()[:-1])
  File "/usr/local/lib/python3.7/socket.py", line 589, in readinto
    return self._sock.recv_into(b)
  File "/home/airflow/.local/lib/python3.7/site-packages/airflow/models/taskinstance.py", line 1410, in signal_handler
    raise AirflowException("Task received SIGTERM signal")
airflow.exceptions.AirflowException: Task received SIGTERM signal

During handling of the above exception, another exception occurred:

Traceback (most recent call last):
  File "/opt/spark/python/lib/py4j-0.10.9.3-src.zip/py4j/java_gateway.py", line 1038, in send_command
    response = connection.send_command(command)
  File "/opt/spark/python/lib/py4j-0.10.9.3-src.zip/py4j/clientserver.py", line 504, in send_command
    "Error while sending or receiving", e, proto.ERROR_ON_RECEIVE)
py4j.protocol.Py4JNetworkError: Error while sending or receiving
[2023-03-29 16:39:42,799] {taskinstance.py:1700} ERROR - Task failed with exception
Traceback (most recent call last):
  File "/home/airflow/.local/lib/python3.7/site-packages/airflow/models/taskinstance.py", line 1329, in _run_raw_task
    self._execute_task_with_callbacks(context)
  File "/home/airflow/.local/lib/python3.7/site-packages/airflow/models/taskinstance.py", line 1455, in _execute_task_with_callbacks
    result = self._execute_task(context, self.task)
  File "/home/airflow/.local/lib/python3.7/site-packages/airflow/models/taskinstance.py", line 1511, in _execute_task
    result = execute_callable(context=context)
  File "/home/airflow/.local/lib/python3.7/site-packages/airflow/operators/python.py", line 174, in execute
    return_value = self.execute_callable()
  File "/home/airflow/.local/lib/python3.7/site-packages/airflow/operators/python.py", line 185, in execute_callable
    return self.python_callable(*self.op_args, **self.op_kwargs)
  File "/opt/airflow/dags/stock_data_transform.py", line 24, in transform_stock_data
    sc = SparkContext(conf=conf)
  File "/opt/spark/python/pyspark/context.py", line 147, in __init__
    conf, jsc, profiler_cls)
  File "/opt/spark/python/pyspark/context.py", line 209, in _do_init
    self._jsc = jsc or self._initialize_context(self._conf._jconf)
  File "/opt/spark/python/pyspark/context.py", line 329, in _initialize_context
    return self._jvm.JavaSparkContext(jconf)
  File "/opt/spark/python/lib/py4j-0.10.9.3-src.zip/py4j/java_gateway.py", line 1586, in __call__
    answer, self._gateway_client, None, self._fqn)
  File "/opt/spark/python/lib/py4j-0.10.9.3-src.zip/py4j/protocol.py", line 336, in get_return_value
    format(target_id, ".", name))
py4j.protocol.Py4JError: An error occurred while calling None.org.apache.spark.api.java.JavaSparkContext
[2023-03-29 16:39:42,944] {taskinstance.py:1277} INFO - Marking task as UP_FOR_RETRY. dag_id=SP_500_DATA_PIPELINE_v1, task_id=transform_data_task, execution_date=20230329T163842, start_date=20230329T163906, end_date=20230329T163942
[2023-03-29 16:39:43,060] {standard_task_runner.py:92} ERROR - Failed to execute job 147 for task transform_data_task
Traceback (most recent call last):
  File "/home/airflow/.local/lib/python3.7/site-packages/airflow/task/task_runner/standard_task_runner.py", line 85, in _start_by_fork
    args.func(args, dag=self.dag)
  File "/home/airflow/.local/lib/python3.7/site-packages/airflow/cli/cli_parser.py", line 48, in command
    return func(*args, **kwargs)
  File "/home/airflow/.local/lib/python3.7/site-packages/airflow/utils/cli.py", line 92, in wrapper
    return f(*args, **kwargs)
  File "/home/airflow/.local/lib/python3.7/site-packages/airflow/cli/commands/task_command.py", line 298, in task_run
    _run_task_by_selected_method(args, dag, ti)
  File "/home/airflow/.local/lib/python3.7/site-packages/airflow/cli/commands/task_command.py", line 107, in _run_task_by_selected_method
    _run_raw_task(args, ti)
  File "/home/airflow/.local/lib/python3.7/site-packages/airflow/cli/commands/task_command.py", line 184, in _run_raw_task
    error_file=args.error_file,
  File "/home/airflow/.local/lib/python3.7/site-packages/airflow/utils/session.py", line 70, in wrapper
    return func(*args, session=session, **kwargs)
  File "/home/airflow/.local/lib/python3.7/site-packages/airflow/models/taskinstance.py", line 1329, in _run_raw_task
    self._execute_task_with_callbacks(context)
  File "/home/airflow/.local/lib/python3.7/site-packages/airflow/models/taskinstance.py", line 1455, in _execute_task_with_callbacks
    result = self._execute_task(context, self.task)
  File "/home/airflow/.local/lib/python3.7/site-packages/airflow/models/taskinstance.py", line 1511, in _execute_task
    result = execute_callable(context=context)
  File "/home/airflow/.local/lib/python3.7/site-packages/airflow/operators/python.py", line 174, in execute
    return_value = self.execute_callable()
  File "/home/airflow/.local/lib/python3.7/site-packages/airflow/operators/python.py", line 185, in execute_callable
    return self.python_callable(*self.op_args, **self.op_kwargs)
  File "/opt/airflow/dags/stock_data_transform.py", line 24, in transform_stock_data
    sc = SparkContext(conf=conf)
  File "/opt/spark/python/pyspark/context.py", line 147, in __init__
    conf, jsc, profiler_cls)
  File "/opt/spark/python/pyspark/context.py", line 209, in _do_init
    self._jsc = jsc or self._initialize_context(self._conf._jconf)
  File "/opt/spark/python/pyspark/context.py", line 329, in _initialize_context
    return self._jvm.JavaSparkContext(jconf)
  File "/opt/spark/python/lib/py4j-0.10.9.3-src.zip/py4j/java_gateway.py", line 1586, in __call__
    answer, self._gateway_client, None, self._fqn)
  File "/opt/spark/python/lib/py4j-0.10.9.3-src.zip/py4j/protocol.py", line 336, in get_return_value
    format(target_id, ".", name))
py4j.protocol.Py4JError: An error occurred while calling None.org.apache.spark.api.java.JavaSparkContext
[2023-03-29 16:39:43,149] {process_utils.py:70} INFO - Process psutil.Process(pid=7456, status='terminated', exitcode=1, started='16:39:05') (7456) terminated with exit code 1
[2023-03-29 16:39:43,918] {process_utils.py:70} INFO - Process psutil.Process(pid=7458, status='terminated', started='16:39:06') (7458) terminated with exit code None
